Internal Server Error: /api/memo_records/update/1/
Traceback (most recent call last):
  File "/Users/dior/Documents/Channel_3rd_Backup_2021_0122/4_Work/Projects/Django-React-Full-Stack/TEST_TU/11_20_Test_Demo_Envi/lib/python3.6/site-packages/django/core/handlers/exception.py", line 47, in inner
    response = get_response(request)
  File "/Users/dior/Documents/Channel_3rd_Backup_2021_0122/4_Work/Projects/Django-React-Full-Stack/TEST_TU/11_20_Test_Demo_Envi/lib/python3.6/site-packages/django/core/handlers/base.py", line 181, in _get_response
    response = wrapped_callback(request, *callback_args, **callback_kwargs)
  File "/Users/dior/Documents/Channel_3rd_Backup_2021_0122/4_Work/Projects/Django-React-Full-Stack/TEST_TU/11_20_Test_Demo_Envi/lib/python3.6/site-packages/django/views/decorators/csrf.py", line 54, in wrapped_view
    return view_func(*args, **kwargs)
  File "/Users/dior/Documents/Channel_3rd_Backup_2021_0122/4_Work/Projects/Django-React-Full-Stack/TEST_TU/11_20_Test_Demo_Envi/lib/python3.6/site-packages/django/views/generic/base.py", line 70, in view
    return self.dispatch(request, *args, **kwargs)
  File "/Users/dior/Documents/Channel_3rd_Backup_2021_0122/4_Work/Projects/Django-React-Full-Stack/TEST_TU/11_20_Test_Demo_Envi/lib/python3.6/site-packages/rest_framework/views.py", line 509, in dispatch
    response = self.handle_exception(exc)
  File "/Users/dior/Documents/Channel_3rd_Backup_2021_0122/4_Work/Projects/Django-React-Full-Stack/TEST_TU/11_20_Test_Demo_Envi/lib/python3.6/site-packages/rest_framework/views.py", line 469, in handle_exception
    self.raise_uncaught_exception(exc)
  File "/Users/dior/Documents/Channel_3rd_Backup_2021_0122/4_Work/Projects/Django-React-Full-Stack/TEST_TU/11_20_Test_Demo_Envi/lib/python3.6/site-packages/rest_framework/views.py", line 480, in raise_uncaught_exception
    raise exc
  File "/Users/dior/Documents/Channel_3rd_Backup_2021_0122/4_Work/Projects/Django-React-Full-Stack/TEST_TU/11_20_Test_Demo_Envi/lib/python3.6/site-packages/rest_framework/views.py", line 506, in dispatch
    response = handler(request, *args, **kwargs)
  File "/Users/dior/Documents/Channel_3rd_Backup_2021_0122/4_Work/Projects/Django-React-Full-Stack/TEST_TU/11_20_Test_Demo_Envi/lib/python3.6/site-packages/rest_framework/generics.py", line 230, in put
    return self.update(request, *args, **kwargs)
  File "/Users/dior/Documents/Channel_3rd_Backup_2021_0122/4_Work/Projects/Django-React-Full-Stack/TEST_TU/11_20_Test_Demo_Envi/lib/python3.6/site-packages/rest_framework/mixins.py", line 68, in update
    self.perform_update(serializer)
  File "/Users/dior/Documents/Channel_3rd_Backup_2021_0122/4_Work/Projects/Django-React-Full-Stack/TEST_TU/backend_Demo_Test/api/views.py", line 104, in perform_update
    updated_memo_history = f"{memo_history}\nReviewed on: {current_date + status_value}"
TypeError: must be str, not NoneType
"PUT /api/memo_records/update/1/ HTTP/1.1" 500 106382
Internal Server Error: /api/memo_records/update/2/
Traceback (most recent call last):
  File "/Users/dior/Documents/Channel_3rd_Backup_2021_0122/4_Work/Projects/Django-React-Full-Stack/TEST_TU/11_20_Test_Demo_Envi/lib/python3.6/site-packages/django/core/handlers/exception.py", line 47, in inner
    response = get_response(request)
  File "/Users/dior/Documents/Channel_3rd_Backup_2021_0122/4_Work/Projects/Django-React-Full-Stack/TEST_TU/11_20_Test_Demo_Envi/lib/python3.6/site-packages/django/core/handlers/base.py", line 181, in _get_response
    response = wrapped_callback(request, *callback_args, **callback_kwargs)
  File "/Users/dior/Documents/Channel_3rd_Backup_2021_0122/4_Work/Projects/Django-React-Full-Stack/TEST_TU/11_20_Test_Demo_Envi/lib/python3.6/site-packages/django/views/decorators/csrf.py", line 54, in wrapped_view
    return view_func(*args, **kwargs)
  File "/Users/dior/Documents/Channel_3rd_Backup_2021_0122/4_Work/Projects/Django-React-Full-Stack/TEST_TU/11_20_Test_Demo_Envi/lib/python3.6/site-packages/django/views/generic/base.py", line 70, in view
    return self.dispatch(request, *args, **kwargs)
  File "/Users/dior/Documents/Channel_3rd_Backup_2021_0122/4_Work/Projects/Django-React-Full-Stack/TEST_TU/11_20_Test_Demo_Envi/lib/python3.6/site-packages/rest_framework/views.py", line 509, in dispatch
    response = self.handle_exception(exc)
  File "/Users/dior/Documents/Channel_3rd_Backup_2021_0122/4_Work/Projects/Django-React-Full-Stack/TEST_TU/11_20_Test_Demo_Envi/lib/python3.6/site-packages/rest_framework/views.py", line 469, in handle_exception
    self.raise_uncaught_exception(exc)
  File "/Users/dior/Documents/Channel_3rd_Backup_2021_0122/4_Work/Projects/Django-React-Full-Stack/TEST_TU/11_20_Test_Demo_Envi/lib/python3.6/site-packages/rest_framework/views.py", line 480, in raise_uncaught_exception
    raise exc
  File "/Users/dior/Documents/Channel_3rd_Backup_2021_0122/4_Work/Projects/Django-React-Full-Stack/TEST_TU/11_20_Test_Demo_Envi/lib/python3.6/site-packages/rest_framework/views.py", line 506, in dispatch
    response = handler(request, *args, **kwargs)
  File "/Users/dior/Documents/Channel_3rd_Backup_2021_0122/4_Work/Projects/Django-React-Full-Stack/TEST_TU/11_20_Test_Demo_Envi/lib/python3.6/site-packages/rest_framework/generics.py", line 230, in put
    return self.update(request, *args, **kwargs)
  File "/Users/dior/Documents/Channel_3rd_Backup_2021_0122/4_Work/Projects/Django-React-Full-Stack/TEST_TU/11_20_Test_Demo_Envi/lib/python3.6/site-packages/rest_framework/mixins.py", line 68, in update
    self.perform_update(serializer)
  File "/Users/dior/Documents/Channel_3rd_Backup_2021_0122/4_Work/Projects/Django-React-Full-Stack/TEST_TU/backend_Demo_Test/api/views.py", line 104, in perform_update
    updated_memo_history = f"{memo_history}\nReviewed on: {current_date + status_value}"
TypeError: must be str, not NoneType
"PUT /api/memo_records/update/2/ HTTP/1.1" 500 106046
Internal Server Error: /api/memo_records/update/1/
Traceback (most recent call last):
  File "/Users/dior/Documents/Channel_3rd_Backup_2021_0122/4_Work/Projects/Django-React-Full-Stack/TEST_TU/11_20_Test_Demo_Envi/lib/python3.6/site-packages/django/core/handlers/exception.py", line 47, in inner
    response = get_response(request)
  File "/Users/dior/Documents/Channel_3rd_Backup_2021_0122/4_Work/Projects/Django-React-Full-Stack/TEST_TU/11_20_Test_Demo_Envi/lib/python3.6/site-packages/django/core/handlers/base.py", line 181, in _get_response
    response = wrapped_callback(request, *callback_args, **callback_kwargs)
  File "/Users/dior/Documents/Channel_3rd_Backup_2021_0122/4_Work/Projects/Django-React-Full-Stack/TEST_TU/11_20_Test_Demo_Envi/lib/python3.6/site-packages/django/views/decorators/csrf.py", line 54, in wrapped_view
    return view_func(*args, **kwargs)
  File "/Users/dior/Documents/Channel_3rd_Backup_2021_0122/4_Work/Projects/Django-React-Full-Stack/TEST_TU/11_20_Test_Demo_Envi/lib/python3.6/site-packages/django/views/generic/base.py", line 70, in view
    return self.dispatch(request, *args, **kwargs)
  File "/Users/dior/Documents/Channel_3rd_Backup_2021_0122/4_Work/Projects/Django-React-Full-Stack/TEST_TU/11_20_Test_Demo_Envi/lib/python3.6/site-packages/rest_framework/views.py", line 509, in dispatch
    response = self.handle_exception(exc)
  File "/Users/dior/Documents/Channel_3rd_Backup_2021_0122/4_Work/Projects/Django-React-Full-Stack/TEST_TU/11_20_Test_Demo_Envi/lib/python3.6/site-packages/rest_framework/views.py", line 469, in handle_exception
    self.raise_uncaught_exception(exc)
  File "/Users/dior/Documents/Channel_3rd_Backup_2021_0122/4_Work/Projects/Django-React-Full-Stack/TEST_TU/11_20_Test_Demo_Envi/lib/python3.6/site-packages/rest_framework/views.py", line 480, in raise_uncaught_exception
    raise exc
  File "/Users/dior/Documents/Channel_3rd_Backup_2021_0122/4_Work/Projects/Django-React-Full-Stack/TEST_TU/11_20_Test_Demo_Envi/lib/python3.6/site-packages/rest_framework/views.py", line 506, in dispatch
    response = handler(request, *args, **kwargs)
  File "/Users/dior/Documents/Channel_3rd_Backup_2021_0122/4_Work/Projects/Django-React-Full-Stack/TEST_TU/11_20_Test_Demo_Envi/lib/python3.6/site-packages/rest_framework/generics.py", line 230, in put
    return self.update(request, *args, **kwargs)
  File "/Users/dior/Documents/Channel_3rd_Backup_2021_0122/4_Work/Projects/Django-React-Full-Stack/TEST_TU/11_20_Test_Demo_Envi/lib/python3.6/site-packages/rest_framework/mixins.py", line 68, in update
    self.perform_update(serializer)
  File "/Users/dior/Documents/Channel_3rd_Backup_2021_0122/4_Work/Projects/Django-React-Full-Stack/TEST_TU/backend_Demo_Test/api/views.py", line 104, in perform_update
    updated_memo_history = f"{memo_history}\nReviewed on: {current_date + status_value}"
TypeError: must be str, not NoneType
"PUT /api/memo_records/update/1/ HTTP/1.1" 500 106739
Internal Server Error: /api/memo_records/update/1/
Traceback (most recent call last):
  File "/Users/dior/Documents/Channel_3rd_Backup_2021_0122/4_Work/Projects/Django-React-Full-Stack/TEST_TU/11_20_Test_Demo_Envi/lib/python3.6/site-packages/django/core/handlers/exception.py", line 47, in inner
    response = get_response(request)
  File "/Users/dior/Documents/Channel_3rd_Backup_2021_0122/4_Work/Projects/Django-React-Full-Stack/TEST_TU/11_20_Test_Demo_Envi/lib/python3.6/site-packages/django/core/handlers/base.py", line 181, in _get_response
    response = wrapped_callback(request, *callback_args, **callback_kwargs)
  File "/Users/dior/Documents/Channel_3rd_Backup_2021_0122/4_Work/Projects/Django-React-Full-Stack/TEST_TU/11_20_Test_Demo_Envi/lib/python3.6/site-packages/django/views/decorators/csrf.py", line 54, in wrapped_view
    return view_func(*args, **kwargs)
  File "/Users/dior/Documents/Channel_3rd_Backup_2021_0122/4_Work/Projects/Django-React-Full-Stack/TEST_TU/11_20_Test_Demo_Envi/lib/python3.6/site-packages/django/views/generic/base.py", line 70, in view
    return self.dispatch(request, *args, **kwargs)
  File "/Users/dior/Documents/Channel_3rd_Backup_2021_0122/4_Work/Projects/Django-React-Full-Stack/TEST_TU/11_20_Test_Demo_Envi/lib/python3.6/site-packages/rest_framework/views.py", line 509, in dispatch
    response = self.handle_exception(exc)
  File "/Users/dior/Documents/Channel_3rd_Backup_2021_0122/4_Work/Projects/Django-React-Full-Stack/TEST_TU/11_20_Test_Demo_Envi/lib/python3.6/site-packages/rest_framework/views.py", line 469, in handle_exception
    self.raise_uncaught_exception(exc)
  File "/Users/dior/Documents/Channel_3rd_Backup_2021_0122/4_Work/Projects/Django-React-Full-Stack/TEST_TU/11_20_Test_Demo_Envi/lib/python3.6/site-packages/rest_framework/views.py", line 480, in raise_uncaught_exception
    raise exc
  File "/Users/dior/Documents/Channel_3rd_Backup_2021_0122/4_Work/Projects/Django-React-Full-Stack/TEST_TU/11_20_Test_Demo_Envi/lib/python3.6/site-packages/rest_framework/views.py", line 506, in dispatch
    response = handler(request, *args, **kwargs)
  File "/Users/dior/Documents/Channel_3rd_Backup_2021_0122/4_Work/Projects/Django-React-Full-Stack/TEST_TU/11_20_Test_Demo_Envi/lib/python3.6/site-packages/rest_framework/generics.py", line 230, in put
    return self.update(request, *args, **kwargs)
  File "/Users/dior/Documents/Channel_3rd_Backup_2021_0122/4_Work/Projects/Django-React-Full-Stack/TEST_TU/11_20_Test_Demo_Envi/lib/python3.6/site-packages/rest_framework/mixins.py", line 68, in update
    self.perform_update(serializer)
  File "/Users/dior/Documents/Channel_3rd_Backup_2021_0122/4_Work/Projects/Django-React-Full-Stack/TEST_TU/backend_Demo_Test/api/views.py", line 98, in perform_update
    print("self.request.headers = " + self.request.headers)
TypeError: must be str, not HttpHeaders
Internal Server Error: /api/memo_records/update/1/
Traceback (most recent call last):
  File "/Users/dior/Documents/Channel_3rd_Backup_2021_0122/4_Work/Projects/Django-React-Full-Stack/TEST_TU/11_20_Test_Demo_Envi/lib/python3.6/site-packages/django/core/handlers/exception.py", line 47, in inner
    response = get_response(request)
  File "/Users/dior/Documents/Channel_3rd_Backup_2021_0122/4_Work/Projects/Django-React-Full-Stack/TEST_TU/11_20_Test_Demo_Envi/lib/python3.6/site-packages/django/core/handlers/base.py", line 181, in _get_response
    response = wrapped_callback(request, *callback_args, **callback_kwargs)
  File "/Users/dior/Documents/Channel_3rd_Backup_2021_0122/4_Work/Projects/Django-React-Full-Stack/TEST_TU/11_20_Test_Demo_Envi/lib/python3.6/site-packages/django/views/decorators/csrf.py", line 54, in wrapped_view
    return view_func(*args, **kwargs)
  File "/Users/dior/Documents/Channel_3rd_Backup_2021_0122/4_Work/Projects/Django-React-Full-Stack/TEST_TU/11_20_Test_Demo_Envi/lib/python3.6/site-packages/django/views/generic/base.py", line 70, in view
    return self.dispatch(request, *args, **kwargs)
  File "/Users/dior/Documents/Channel_3rd_Backup_2021_0122/4_Work/Projects/Django-React-Full-Stack/TEST_TU/11_20_Test_Demo_Envi/lib/python3.6/site-packages/rest_framework/views.py", line 509, in dispatch
    response = self.handle_exception(exc)
  File "/Users/dior/Documents/Channel_3rd_Backup_2021_0122/4_Work/Projects/Django-React-Full-Stack/TEST_TU/11_20_Test_Demo_Envi/lib/python3.6/site-packages/rest_framework/views.py", line 469, in handle_exception
    self.raise_uncaught_exception(exc)
  File "/Users/dior/Documents/Channel_3rd_Backup_2021_0122/4_Work/Projects/Django-React-Full-Stack/TEST_TU/11_20_Test_Demo_Envi/lib/python3.6/site-packages/rest_framework/views.py", line 480, in raise_uncaught_exception
    raise exc
  File "/Users/dior/Documents/Channel_3rd_Backup_2021_0122/4_Work/Projects/Django-React-Full-Stack/TEST_TU/11_20_Test_Demo_Envi/lib/python3.6/site-packages/rest_framework/views.py", line 506, in dispatch
    response = handler(request, *args, **kwargs)
  File "/Users/dior/Documents/Channel_3rd_Backup_2021_0122/4_Work/Projects/Django-React-Full-Stack/TEST_TU/11_20_Test_Demo_Envi/lib/python3.6/site-packages/rest_framework/generics.py", line 230, in put
    return self.update(request, *args, **kwargs)
  File "/Users/dior/Documents/Channel_3rd_Backup_2021_0122/4_Work/Projects/Django-React-Full-Stack/TEST_TU/11_20_Test_Demo_Envi/lib/python3.6/site-packages/rest_framework/mixins.py", line 68, in update
    self.perform_update(serializer)
  File "/Users/dior/Documents/Channel_3rd_Backup_2021_0122/4_Work/Projects/Django-React-Full-Stack/TEST_TU/backend_Demo_Test/api/views.py", line 98, in perform_update
    print("self.request.headers = " + self.request.headers)
TypeError: must be str, not HttpHeaders
"PUT /api/memo_records/update/1/ HTTP/1.1" 500 106049
"PUT /api/memo_records/update/1/ HTTP/1.1" 500 106203
Internal Server Error: /api/memo_records/update/1/
Traceback (most recent call last):
  File "/Users/dior/Documents/Channel_3rd_Backup_2021_0122/4_Work/Projects/Django-React-Full-Stack/TEST_TU/11_20_Test_Demo_Envi/lib/python3.6/site-packages/django/core/handlers/exception.py", line 47, in inner
    response = get_response(request)
  File "/Users/dior/Documents/Channel_3rd_Backup_2021_0122/4_Work/Projects/Django-React-Full-Stack/TEST_TU/11_20_Test_Demo_Envi/lib/python3.6/site-packages/django/core/handlers/base.py", line 181, in _get_response
    response = wrapped_callback(request, *callback_args, **callback_kwargs)
  File "/Users/dior/Documents/Channel_3rd_Backup_2021_0122/4_Work/Projects/Django-React-Full-Stack/TEST_TU/11_20_Test_Demo_Envi/lib/python3.6/site-packages/django/views/decorators/csrf.py", line 54, in wrapped_view
    return view_func(*args, **kwargs)
  File "/Users/dior/Documents/Channel_3rd_Backup_2021_0122/4_Work/Projects/Django-React-Full-Stack/TEST_TU/11_20_Test_Demo_Envi/lib/python3.6/site-packages/django/views/generic/base.py", line 70, in view
    return self.dispatch(request, *args, **kwargs)
  File "/Users/dior/Documents/Channel_3rd_Backup_2021_0122/4_Work/Projects/Django-React-Full-Stack/TEST_TU/11_20_Test_Demo_Envi/lib/python3.6/site-packages/rest_framework/views.py", line 509, in dispatch
    response = self.handle_exception(exc)
  File "/Users/dior/Documents/Channel_3rd_Backup_2021_0122/4_Work/Projects/Django-React-Full-Stack/TEST_TU/11_20_Test_Demo_Envi/lib/python3.6/site-packages/rest_framework/views.py", line 469, in handle_exception
    self.raise_uncaught_exception(exc)
  File "/Users/dior/Documents/Channel_3rd_Backup_2021_0122/4_Work/Projects/Django-React-Full-Stack/TEST_TU/11_20_Test_Demo_Envi/lib/python3.6/site-packages/rest_framework/views.py", line 480, in raise_uncaught_exception
    raise exc
  File "/Users/dior/Documents/Channel_3rd_Backup_2021_0122/4_Work/Projects/Django-React-Full-Stack/TEST_TU/11_20_Test_Demo_Envi/lib/python3.6/site-packages/rest_framework/views.py", line 506, in dispatch
    response = handler(request, *args, **kwargs)
  File "/Users/dior/Documents/Channel_3rd_Backup_2021_0122/4_Work/Projects/Django-React-Full-Stack/TEST_TU/11_20_Test_Demo_Envi/lib/python3.6/site-packages/rest_framework/generics.py", line 230, in put
    return self.update(request, *args, **kwargs)
  File "/Users/dior/Documents/Channel_3rd_Backup_2021_0122/4_Work/Projects/Django-React-Full-Stack/TEST_TU/11_20_Test_Demo_Envi/lib/python3.6/site-packages/rest_framework/mixins.py", line 68, in update
    self.perform_update(serializer)
  File "/Users/dior/Documents/Channel_3rd_Backup_2021_0122/4_Work/Projects/Django-React-Full-Stack/TEST_TU/backend_Demo_Test/api/views.py", line 97, in perform_update
    print("self.request.headers = " + self.request.headers)
TypeError: must be str, not HttpHeaders
Internal Server Error: /api/memo_records/update/1/
Traceback (most recent call last):
  File "/Users/dior/Documents/Channel_3rd_Backup_2021_0122/4_Work/Projects/Django-React-Full-Stack/TEST_TU/11_20_Test_Demo_Envi/lib/python3.6/site-packages/django/core/handlers/exception.py", line 47, in inner
    response = get_response(request)
  File "/Users/dior/Documents/Channel_3rd_Backup_2021_0122/4_Work/Projects/Django-React-Full-Stack/TEST_TU/11_20_Test_Demo_Envi/lib/python3.6/site-packages/django/core/handlers/base.py", line 181, in _get_response
    response = wrapped_callback(request, *callback_args, **callback_kwargs)
  File "/Users/dior/Documents/Channel_3rd_Backup_2021_0122/4_Work/Projects/Django-React-Full-Stack/TEST_TU/11_20_Test_Demo_Envi/lib/python3.6/site-packages/django/views/decorators/csrf.py", line 54, in wrapped_view
    return view_func(*args, **kwargs)
  File "/Users/dior/Documents/Channel_3rd_Backup_2021_0122/4_Work/Projects/Django-React-Full-Stack/TEST_TU/11_20_Test_Demo_Envi/lib/python3.6/site-packages/django/views/generic/base.py", line 70, in view
    return self.dispatch(request, *args, **kwargs)
  File "/Users/dior/Documents/Channel_3rd_Backup_2021_0122/4_Work/Projects/Django-React-Full-Stack/TEST_TU/11_20_Test_Demo_Envi/lib/python3.6/site-packages/rest_framework/views.py", line 509, in dispatch
    response = self.handle_exception(exc)
  File "/Users/dior/Documents/Channel_3rd_Backup_2021_0122/4_Work/Projects/Django-React-Full-Stack/TEST_TU/11_20_Test_Demo_Envi/lib/python3.6/site-packages/rest_framework/views.py", line 469, in handle_exception
    self.raise_uncaught_exception(exc)
  File "/Users/dior/Documents/Channel_3rd_Backup_2021_0122/4_Work/Projects/Django-React-Full-Stack/TEST_TU/11_20_Test_Demo_Envi/lib/python3.6/site-packages/rest_framework/views.py", line 480, in raise_uncaught_exception
    raise exc
  File "/Users/dior/Documents/Channel_3rd_Backup_2021_0122/4_Work/Projects/Django-React-Full-Stack/TEST_TU/11_20_Test_Demo_Envi/lib/python3.6/site-packages/rest_framework/views.py", line 506, in dispatch
    response = handler(request, *args, **kwargs)
  File "/Users/dior/Documents/Channel_3rd_Backup_2021_0122/4_Work/Projects/Django-React-Full-Stack/TEST_TU/11_20_Test_Demo_Envi/lib/python3.6/site-packages/rest_framework/generics.py", line 230, in put
    return self.update(request, *args, **kwargs)
  File "/Users/dior/Documents/Channel_3rd_Backup_2021_0122/4_Work/Projects/Django-React-Full-Stack/TEST_TU/11_20_Test_Demo_Envi/lib/python3.6/site-packages/rest_framework/mixins.py", line 68, in update
    self.perform_update(serializer)
  File "/Users/dior/Documents/Channel_3rd_Backup_2021_0122/4_Work/Projects/Django-React-Full-Stack/TEST_TU/backend_Demo_Test/api/views.py", line 97, in perform_update
    print("self.request.headers = " + self.request.headers)
TypeError: must be str, not HttpHeaders
"PUT /api/memo_records/update/1/ HTTP/1.1" 500 106243
"PUT /api/memo_records/update/1/ HTTP/1.1" 500 106111
Internal Server Error: /api/memo_records/
Traceback (most recent call last):
  File "/Users/dior/Documents/Channel_3rd_Backup_2021_0122/4_Work/Projects/Django-React-Full-Stack/TEST_TU/11_20_Test_Demo_Envi/lib/python3.6/site-packages/django/db/backends/utils.py", line 84, in _execute
    return self.cursor.execute(sql, params)
  File "/Users/dior/Documents/Channel_3rd_Backup_2021_0122/4_Work/Projects/Django-React-Full-Stack/TEST_TU/11_20_Test_Demo_Envi/lib/python3.6/site-packages/django/db/backends/sqlite3/base.py", line 423, in execute
    return Database.Cursor.execute(self, query, params)
sqlite3.OperationalError: no such table: api_memorecord

The above exception was the direct cause of the following exception:

Traceback (most recent call last):
  File "/Users/dior/Documents/Channel_3rd_Backup_2021_0122/4_Work/Projects/Django-React-Full-Stack/TEST_TU/11_20_Test_Demo_Envi/lib/python3.6/site-packages/django/core/handlers/exception.py", line 47, in inner
    response = get_response(request)
  File "/Users/dior/Documents/Channel_3rd_Backup_2021_0122/4_Work/Projects/Django-React-Full-Stack/TEST_TU/11_20_Test_Demo_Envi/lib/python3.6/site-packages/django/core/handlers/base.py", line 181, in _get_response
    response = wrapped_callback(request, *callback_args, **callback_kwargs)
  File "/Users/dior/Documents/Channel_3rd_Backup_2021_0122/4_Work/Projects/Django-React-Full-Stack/TEST_TU/11_20_Test_Demo_Envi/lib/python3.6/site-packages/django/views/decorators/csrf.py", line 54, in wrapped_view
    return view_func(*args, **kwargs)
  File "/Users/dior/Documents/Channel_3rd_Backup_2021_0122/4_Work/Projects/Django-React-Full-Stack/TEST_TU/11_20_Test_Demo_Envi/lib/python3.6/site-packages/django/views/generic/base.py", line 70, in view
    return self.dispatch(request, *args, **kwargs)
  File "/Users/dior/Documents/Channel_3rd_Backup_2021_0122/4_Work/Projects/Django-React-Full-Stack/TEST_TU/11_20_Test_Demo_Envi/lib/python3.6/site-packages/rest_framework/views.py", line 509, in dispatch
    response = self.handle_exception(exc)
  File "/Users/dior/Documents/Channel_3rd_Backup_2021_0122/4_Work/Projects/Django-React-Full-Stack/TEST_TU/11_20_Test_Demo_Envi/lib/python3.6/site-packages/rest_framework/views.py", line 469, in handle_exception
    self.raise_uncaught_exception(exc)
  File "/Users/dior/Documents/Channel_3rd_Backup_2021_0122/4_Work/Projects/Django-React-Full-Stack/TEST_TU/11_20_Test_Demo_Envi/lib/python3.6/site-packages/rest_framework/views.py", line 480, in raise_uncaught_exception
    raise exc
  File "/Users/dior/Documents/Channel_3rd_Backup_2021_0122/4_Work/Projects/Django-React-Full-Stack/TEST_TU/11_20_Test_Demo_Envi/lib/python3.6/site-packages/rest_framework/views.py", line 506, in dispatch
    response = handler(request, *args, **kwargs)
  File "/Users/dior/Documents/Channel_3rd_Backup_2021_0122/4_Work/Projects/Django-React-Full-Stack/TEST_TU/11_20_Test_Demo_Envi/lib/python3.6/site-packages/rest_framework/generics.py", line 243, in get
    return self.list(request, *args, **kwargs)
  File "/Users/dior/Documents/Channel_3rd_Backup_2021_0122/4_Work/Projects/Django-React-Full-Stack/TEST_TU/11_20_Test_Demo_Envi/lib/python3.6/site-packages/rest_framework/mixins.py", line 46, in list
    return Response(serializer.data)
  File "/Users/dior/Documents/Channel_3rd_Backup_2021_0122/4_Work/Projects/Django-React-Full-Stack/TEST_TU/11_20_Test_Demo_Envi/lib/python3.6/site-packages/rest_framework/serializers.py", line 795, in data
    ret = super().data
  File "/Users/dior/Documents/Channel_3rd_Backup_2021_0122/4_Work/Projects/Django-React-Full-Stack/TEST_TU/11_20_Test_Demo_Envi/lib/python3.6/site-packages/rest_framework/serializers.py", line 249, in data
    self._data = self.to_representation(self.instance)
  File "/Users/dior/Documents/Channel_3rd_Backup_2021_0122/4_Work/Projects/Django-React-Full-Stack/TEST_TU/11_20_Test_Demo_Envi/lib/python3.6/site-packages/rest_framework/serializers.py", line 714, in to_representation
    self.child.to_representation(item) for item in iterable
  File "/Users/dior/Documents/Channel_3rd_Backup_2021_0122/4_Work/Projects/Django-React-Full-Stack/TEST_TU/11_20_Test_Demo_Envi/lib/python3.6/site-packages/django/db/models/query.py", line 280, in __iter__
    self._fetch_all()
  File "/Users/dior/Documents/Channel_3rd_Backup_2021_0122/4_Work/Projects/Django-React-Full-Stack/TEST_TU/11_20_Test_Demo_Envi/lib/python3.6/site-packages/django/db/models/query.py", line 1324, in _fetch_all
    self._result_cache = list(self._iterable_class(self))
  File "/Users/dior/Documents/Channel_3rd_Backup_2021_0122/4_Work/Projects/Django-React-Full-Stack/TEST_TU/11_20_Test_Demo_Envi/lib/python3.6/site-packages/django/db/models/query.py", line 51, in __iter__
    results = compiler.execute_sql(chunked_fetch=self.chunked_fetch, chunk_size=self.chunk_size)
  File "/Users/dior/Documents/Channel_3rd_Backup_2021_0122/4_Work/Projects/Django-React-Full-Stack/TEST_TU/11_20_Test_Demo_Envi/lib/python3.6/site-packages/django/db/models/sql/compiler.py", line 1175, in execute_sql
    cursor.execute(sql, params)
  File "/Users/dior/Documents/Channel_3rd_Backup_2021_0122/4_Work/Projects/Django-React-Full-Stack/TEST_TU/11_20_Test_Demo_Envi/lib/python3.6/site-packages/django/db/backends/utils.py", line 98, in execute
    return super().execute(sql, params)
  File "/Users/dior/Documents/Channel_3rd_Backup_2021_0122/4_Work/Projects/Django-React-Full-Stack/TEST_TU/11_20_Test_Demo_Envi/lib/python3.6/site-packages/django/db/backends/utils.py", line 66, in execute
    return self._execute_with_wrappers(sql, params, many=False, executor=self._execute)
  File "/Users/dior/Documents/Channel_3rd_Backup_2021_0122/4_Work/Projects/Django-React-Full-Stack/TEST_TU/11_20_Test_Demo_Envi/lib/python3.6/site-packages/django/db/backends/utils.py", line 75, in _execute_with_wrappers
    return executor(sql, params, many, context)
  File "/Users/dior/Documents/Channel_3rd_Backup_2021_0122/4_Work/Projects/Django-React-Full-Stack/TEST_TU/11_20_Test_Demo_Envi/lib/python3.6/site-packages/django/db/backends/utils.py", line 84, in _execute
    return self.cursor.execute(sql, params)
  File "/Users/dior/Documents/Channel_3rd_Backup_2021_0122/4_Work/Projects/Django-React-Full-Stack/TEST_TU/11_20_Test_Demo_Envi/lib/python3.6/site-packages/django/db/utils.py", line 90, in __exit__
    raise dj_exc_value.with_traceback(traceback) from exc_value
  File "/Users/dior/Documents/Channel_3rd_Backup_2021_0122/4_Work/Projects/Django-React-Full-Stack/TEST_TU/11_20_Test_Demo_Envi/lib/python3.6/site-packages/django/db/backends/utils.py", line 84, in _execute
    return self.cursor.execute(sql, params)
  File "/Users/dior/Documents/Channel_3rd_Backup_2021_0122/4_Work/Projects/Django-React-Full-Stack/TEST_TU/11_20_Test_Demo_Envi/lib/python3.6/site-packages/django/db/backends/sqlite3/base.py", line 423, in execute
    return Database.Cursor.execute(self, query, params)
django.db.utils.OperationalError: no such table: api_memorecord
"GET /api/memo_records/ HTTP/1.1" 500 179472
Internal Server Error: /api/memo_records/
Traceback (most recent call last):
  File "/Users/dior/Documents/Channel_3rd_Backup_2021_0122/4_Work/Projects/Django-React-Full-Stack/TEST_TU/11_20_Test_Demo_Envi/lib/python3.6/site-packages/django/db/backends/utils.py", line 84, in _execute
    return self.cursor.execute(sql, params)
  File "/Users/dior/Documents/Channel_3rd_Backup_2021_0122/4_Work/Projects/Django-React-Full-Stack/TEST_TU/11_20_Test_Demo_Envi/lib/python3.6/site-packages/django/db/backends/sqlite3/base.py", line 423, in execute
    return Database.Cursor.execute(self, query, params)
sqlite3.OperationalError: no such table: api_memorecord

The above exception was the direct cause of the following exception:

Traceback (most recent call last):
  File "/Users/dior/Documents/Channel_3rd_Backup_2021_0122/4_Work/Projects/Django-React-Full-Stack/TEST_TU/11_20_Test_Demo_Envi/lib/python3.6/site-packages/django/core/handlers/exception.py", line 47, in inner
    response = get_response(request)
  File "/Users/dior/Documents/Channel_3rd_Backup_2021_0122/4_Work/Projects/Django-React-Full-Stack/TEST_TU/11_20_Test_Demo_Envi/lib/python3.6/site-packages/django/core/handlers/base.py", line 181, in _get_response
    response = wrapped_callback(request, *callback_args, **callback_kwargs)
  File "/Users/dior/Documents/Channel_3rd_Backup_2021_0122/4_Work/Projects/Django-React-Full-Stack/TEST_TU/11_20_Test_Demo_Envi/lib/python3.6/site-packages/django/views/decorators/csrf.py", line 54, in wrapped_view
    return view_func(*args, **kwargs)
  File "/Users/dior/Documents/Channel_3rd_Backup_2021_0122/4_Work/Projects/Django-React-Full-Stack/TEST_TU/11_20_Test_Demo_Envi/lib/python3.6/site-packages/django/views/generic/base.py", line 70, in view
    return self.dispatch(request, *args, **kwargs)
  File "/Users/dior/Documents/Channel_3rd_Backup_2021_0122/4_Work/Projects/Django-React-Full-Stack/TEST_TU/11_20_Test_Demo_Envi/lib/python3.6/site-packages/rest_framework/views.py", line 509, in dispatch
    response = self.handle_exception(exc)
  File "/Users/dior/Documents/Channel_3rd_Backup_2021_0122/4_Work/Projects/Django-React-Full-Stack/TEST_TU/11_20_Test_Demo_Envi/lib/python3.6/site-packages/rest_framework/views.py", line 469, in handle_exception
    self.raise_uncaught_exception(exc)
  File "/Users/dior/Documents/Channel_3rd_Backup_2021_0122/4_Work/Projects/Django-React-Full-Stack/TEST_TU/11_20_Test_Demo_Envi/lib/python3.6/site-packages/rest_framework/views.py", line 480, in raise_uncaught_exception
    raise exc
  File "/Users/dior/Documents/Channel_3rd_Backup_2021_0122/4_Work/Projects/Django-React-Full-Stack/TEST_TU/11_20_Test_Demo_Envi/lib/python3.6/site-packages/rest_framework/views.py", line 506, in dispatch
    response = handler(request, *args, **kwargs)
  File "/Users/dior/Documents/Channel_3rd_Backup_2021_0122/4_Work/Projects/Django-React-Full-Stack/TEST_TU/11_20_Test_Demo_Envi/lib/python3.6/site-packages/rest_framework/generics.py", line 243, in get
    return self.list(request, *args, **kwargs)
  File "/Users/dior/Documents/Channel_3rd_Backup_2021_0122/4_Work/Projects/Django-React-Full-Stack/TEST_TU/11_20_Test_Demo_Envi/lib/python3.6/site-packages/rest_framework/mixins.py", line 46, in list
    return Response(serializer.data)
  File "/Users/dior/Documents/Channel_3rd_Backup_2021_0122/4_Work/Projects/Django-React-Full-Stack/TEST_TU/11_20_Test_Demo_Envi/lib/python3.6/site-packages/rest_framework/serializers.py", line 795, in data
    ret = super().data
  File "/Users/dior/Documents/Channel_3rd_Backup_2021_0122/4_Work/Projects/Django-React-Full-Stack/TEST_TU/11_20_Test_Demo_Envi/lib/python3.6/site-packages/rest_framework/serializers.py", line 249, in data
    self._data = self.to_representation(self.instance)
  File "/Users/dior/Documents/Channel_3rd_Backup_2021_0122/4_Work/Projects/Django-React-Full-Stack/TEST_TU/11_20_Test_Demo_Envi/lib/python3.6/site-packages/rest_framework/serializers.py", line 714, in to_representation
    self.child.to_representation(item) for item in iterable
  File "/Users/dior/Documents/Channel_3rd_Backup_2021_0122/4_Work/Projects/Django-React-Full-Stack/TEST_TU/11_20_Test_Demo_Envi/lib/python3.6/site-packages/django/db/models/query.py", line 280, in __iter__
    self._fetch_all()
  File "/Users/dior/Documents/Channel_3rd_Backup_2021_0122/4_Work/Projects/Django-React-Full-Stack/TEST_TU/11_20_Test_Demo_Envi/lib/python3.6/site-packages/django/db/models/query.py", line 1324, in _fetch_all
    self._result_cache = list(self._iterable_class(self))
  File "/Users/dior/Documents/Channel_3rd_Backup_2021_0122/4_Work/Projects/Django-React-Full-Stack/TEST_TU/11_20_Test_Demo_Envi/lib/python3.6/site-packages/django/db/models/query.py", line 51, in __iter__
    results = compiler.execute_sql(chunked_fetch=self.chunked_fetch, chunk_size=self.chunk_size)
  File "/Users/dior/Documents/Channel_3rd_Backup_2021_0122/4_Work/Projects/Django-React-Full-Stack/TEST_TU/11_20_Test_Demo_Envi/lib/python3.6/site-packages/django/db/models/sql/compiler.py", line 1175, in execute_sql
    cursor.execute(sql, params)
  File "/Users/dior/Documents/Channel_3rd_Backup_2021_0122/4_Work/Projects/Django-React-Full-Stack/TEST_TU/11_20_Test_Demo_Envi/lib/python3.6/site-packages/django/db/backends/utils.py", line 98, in execute
    return super().execute(sql, params)
  File "/Users/dior/Documents/Channel_3rd_Backup_2021_0122/4_Work/Projects/Django-React-Full-Stack/TEST_TU/11_20_Test_Demo_Envi/lib/python3.6/site-packages/django/db/backends/utils.py", line 66, in execute
    return self._execute_with_wrappers(sql, params, many=False, executor=self._execute)
  File "/Users/dior/Documents/Channel_3rd_Backup_2021_0122/4_Work/Projects/Django-React-Full-Stack/TEST_TU/11_20_Test_Demo_Envi/lib/python3.6/site-packages/django/db/backends/utils.py", line 75, in _execute_with_wrappers
    return executor(sql, params, many, context)
  File "/Users/dior/Documents/Channel_3rd_Backup_2021_0122/4_Work/Projects/Django-React-Full-Stack/TEST_TU/11_20_Test_Demo_Envi/lib/python3.6/site-packages/django/db/backends/utils.py", line 84, in _execute
    return self.cursor.execute(sql, params)
  File "/Users/dior/Documents/Channel_3rd_Backup_2021_0122/4_Work/Projects/Django-React-Full-Stack/TEST_TU/11_20_Test_Demo_Envi/lib/python3.6/site-packages/django/db/utils.py", line 90, in __exit__
    raise dj_exc_value.with_traceback(traceback) from exc_value
  File "/Users/dior/Documents/Channel_3rd_Backup_2021_0122/4_Work/Projects/Django-React-Full-Stack/TEST_TU/11_20_Test_Demo_Envi/lib/python3.6/site-packages/django/db/backends/utils.py", line 84, in _execute
    return self.cursor.execute(sql, params)
  File "/Users/dior/Documents/Channel_3rd_Backup_2021_0122/4_Work/Projects/Django-React-Full-Stack/TEST_TU/11_20_Test_Demo_Envi/lib/python3.6/site-packages/django/db/backends/sqlite3/base.py", line 423, in execute
    return Database.Cursor.execute(self, query, params)
django.db.utils.OperationalError: no such table: api_memorecord
"GET /api/memo_records/ HTTP/1.1" 500 179472
Internal Server Error: /api/memo_records/
Traceback (most recent call last):
  File "/Users/dior/Documents/Channel_3rd_Backup_2021_0122/4_Work/Projects/Django-React-Full-Stack/TEST_TU/11_20_Test_Demo_Envi/lib/python3.6/site-packages/django/core/handlers/exception.py", line 47, in inner
    response = get_response(request)
  File "/Users/dior/Documents/Channel_3rd_Backup_2021_0122/4_Work/Projects/Django-React-Full-Stack/TEST_TU/11_20_Test_Demo_Envi/lib/python3.6/site-packages/django/core/handlers/base.py", line 181, in _get_response
    response = wrapped_callback(request, *callback_args, **callback_kwargs)
  File "/Users/dior/Documents/Channel_3rd_Backup_2021_0122/4_Work/Projects/Django-React-Full-Stack/TEST_TU/11_20_Test_Demo_Envi/lib/python3.6/site-packages/django/views/decorators/csrf.py", line 54, in wrapped_view
    return view_func(*args, **kwargs)
  File "/Users/dior/Documents/Channel_3rd_Backup_2021_0122/4_Work/Projects/Django-React-Full-Stack/TEST_TU/11_20_Test_Demo_Envi/lib/python3.6/site-packages/django/views/generic/base.py", line 70, in view
    return self.dispatch(request, *args, **kwargs)
  File "/Users/dior/Documents/Channel_3rd_Backup_2021_0122/4_Work/Projects/Django-React-Full-Stack/TEST_TU/11_20_Test_Demo_Envi/lib/python3.6/site-packages/rest_framework/views.py", line 509, in dispatch
    response = self.handle_exception(exc)
  File "/Users/dior/Documents/Channel_3rd_Backup_2021_0122/4_Work/Projects/Django-React-Full-Stack/TEST_TU/11_20_Test_Demo_Envi/lib/python3.6/site-packages/rest_framework/views.py", line 469, in handle_exception
    self.raise_uncaught_exception(exc)
  File "/Users/dior/Documents/Channel_3rd_Backup_2021_0122/4_Work/Projects/Django-React-Full-Stack/TEST_TU/11_20_Test_Demo_Envi/lib/python3.6/site-packages/rest_framework/views.py", line 480, in raise_uncaught_exception
    raise exc
  File "/Users/dior/Documents/Channel_3rd_Backup_2021_0122/4_Work/Projects/Django-React-Full-Stack/TEST_TU/11_20_Test_Demo_Envi/lib/python3.6/site-packages/rest_framework/views.py", line 506, in dispatch
    response = handler(request, *args, **kwargs)
  File "/Users/dior/Documents/Channel_3rd_Backup_2021_0122/4_Work/Projects/Django-React-Full-Stack/TEST_TU/11_20_Test_Demo_Envi/lib/python3.6/site-packages/rest_framework/generics.py", line 246, in post
    return self.create(request, *args, **kwargs)
  File "/Users/dior/Documents/Channel_3rd_Backup_2021_0122/4_Work/Projects/Django-React-Full-Stack/TEST_TU/11_20_Test_Demo_Envi/lib/python3.6/site-packages/rest_framework/mixins.py", line 18, in create
    serializer.is_valid(raise_exception=True)
  File "/Users/dior/Documents/Channel_3rd_Backup_2021_0122/4_Work/Projects/Django-React-Full-Stack/TEST_TU/11_20_Test_Demo_Envi/lib/python3.6/site-packages/rest_framework/serializers.py", line 223, in is_valid
    self._validated_data = self.run_validation(self.initial_data)
  File "/Users/dior/Documents/Channel_3rd_Backup_2021_0122/4_Work/Projects/Django-React-Full-Stack/TEST_TU/11_20_Test_Demo_Envi/lib/python3.6/site-packages/rest_framework/serializers.py", line 442, in run_validation
    value = self.to_internal_value(data)
  File "/Users/dior/Documents/Channel_3rd_Backup_2021_0122/4_Work/Projects/Django-React-Full-Stack/TEST_TU/11_20_Test_Demo_Envi/lib/python3.6/site-packages/rest_framework/serializers.py", line 495, in to_internal_value
    for field in fields:
  File "/Users/dior/Documents/Channel_3rd_Backup_2021_0122/4_Work/Projects/Django-React-Full-Stack/TEST_TU/11_20_Test_Demo_Envi/lib/python3.6/site-packages/rest_framework/serializers.py", line 378, in _writable_fields
    for field in self.fields.values():
  File "/Users/dior/Documents/Channel_3rd_Backup_2021_0122/4_Work/Projects/Django-React-Full-Stack/TEST_TU/11_20_Test_Demo_Envi/lib/python3.6/site-packages/django/utils/functional.py", line 48, in __get__
    res = instance.__dict__[self.name] = self.func(instance)
  File "/Users/dior/Documents/Channel_3rd_Backup_2021_0122/4_Work/Projects/Django-React-Full-Stack/TEST_TU/11_20_Test_Demo_Envi/lib/python3.6/site-packages/rest_framework/serializers.py", line 372, in fields
    for key, value in self.get_fields().items():
  File "/Users/dior/Documents/Channel_3rd_Backup_2021_0122/4_Work/Projects/Django-React-Full-Stack/TEST_TU/11_20_Test_Demo_Envi/lib/python3.6/site-packages/rest_framework/serializers.py", line 1104, in get_fields
    source, info, model, depth
  File "/Users/dior/Documents/Channel_3rd_Backup_2021_0122/4_Work/Projects/Django-React-Full-Stack/TEST_TU/11_20_Test_Demo_Envi/lib/python3.6/site-packages/rest_framework/serializers.py", line 1249, in build_field
    return self.build_unknown_field(field_name, model_class)
  File "/Users/dior/Documents/Channel_3rd_Backup_2021_0122/4_Work/Projects/Django-React-Full-Stack/TEST_TU/11_20_Test_Demo_Envi/lib/python3.6/site-packages/rest_framework/serializers.py", line 1369, in build_unknown_field
    (field_name, model_class.__name__, self.__class__.__module__, self.__class__.__name__)
django.core.exceptions.ImproperlyConfigured: Field name `subject_Type` is not valid for model `MemoRecord` in `api.serializers.MemoRecordSerializer`.
"POST /api/memo_records/ HTTP/1.1" 500 146235
Internal Server Error: /api/memo_records/update/1/
Traceback (most recent call last):
  File "/Users/dior/Documents/Channel_3rd_Backup_2021_0122/4_Work/Projects/Django-React-Full-Stack/TEST_TU/11_20_Test_Demo_Envi/lib/python3.6/site-packages/django/core/handlers/exception.py", line 47, in inner
    response = get_response(request)
  File "/Users/dior/Documents/Channel_3rd_Backup_2021_0122/4_Work/Projects/Django-React-Full-Stack/TEST_TU/11_20_Test_Demo_Envi/lib/python3.6/site-packages/django/core/handlers/base.py", line 181, in _get_response
    response = wrapped_callback(request, *callback_args, **callback_kwargs)
  File "/Users/dior/Documents/Channel_3rd_Backup_2021_0122/4_Work/Projects/Django-React-Full-Stack/TEST_TU/11_20_Test_Demo_Envi/lib/python3.6/site-packages/django/views/decorators/csrf.py", line 54, in wrapped_view
    return view_func(*args, **kwargs)
  File "/Users/dior/Documents/Channel_3rd_Backup_2021_0122/4_Work/Projects/Django-React-Full-Stack/TEST_TU/11_20_Test_Demo_Envi/lib/python3.6/site-packages/django/views/generic/base.py", line 70, in view
    return self.dispatch(request, *args, **kwargs)
  File "/Users/dior/Documents/Channel_3rd_Backup_2021_0122/4_Work/Projects/Django-React-Full-Stack/TEST_TU/11_20_Test_Demo_Envi/lib/python3.6/site-packages/rest_framework/views.py", line 509, in dispatch
    response = self.handle_exception(exc)
  File "/Users/dior/Documents/Channel_3rd_Backup_2021_0122/4_Work/Projects/Django-React-Full-Stack/TEST_TU/11_20_Test_Demo_Envi/lib/python3.6/site-packages/rest_framework/views.py", line 469, in handle_exception
    self.raise_uncaught_exception(exc)
  File "/Users/dior/Documents/Channel_3rd_Backup_2021_0122/4_Work/Projects/Django-React-Full-Stack/TEST_TU/11_20_Test_Demo_Envi/lib/python3.6/site-packages/rest_framework/views.py", line 480, in raise_uncaught_exception
    raise exc
  File "/Users/dior/Documents/Channel_3rd_Backup_2021_0122/4_Work/Projects/Django-React-Full-Stack/TEST_TU/11_20_Test_Demo_Envi/lib/python3.6/site-packages/rest_framework/views.py", line 506, in dispatch
    response = handler(request, *args, **kwargs)
  File "/Users/dior/Documents/Channel_3rd_Backup_2021_0122/4_Work/Projects/Django-React-Full-Stack/TEST_TU/11_20_Test_Demo_Envi/lib/python3.6/site-packages/rest_framework/generics.py", line 230, in put
    return self.update(request, *args, **kwargs)
  File "/Users/dior/Documents/Channel_3rd_Backup_2021_0122/4_Work/Projects/Django-React-Full-Stack/TEST_TU/11_20_Test_Demo_Envi/lib/python3.6/site-packages/rest_framework/mixins.py", line 68, in update
    self.perform_update(serializer)
  File "/Users/dior/Documents/Channel_3rd_Backup_2021_0122/4_Work/Projects/Django-React-Full-Stack/TEST_TU/backend_Demo_Test/api/views.py", line 100, in perform_update
    memo_history = instance.memo_History or ''  # 防止 None 出现，默认空字符串
AttributeError: 'MemoRecord' object has no attribute 'memo_History'
"PUT /api/memo_records/update/1/ HTTP/1.1" 500 104079
Internal Server Error: /api/memo_records/update/2/
Traceback (most recent call last):
  File "/Users/dior/Documents/Channel_3rd_Backup_2021_0122/4_Work/Projects/Django-React-Full-Stack/TEST_TU/11_20_Test_Demo_Envi/lib/python3.6/site-packages/django/core/handlers/exception.py", line 47, in inner
    response = get_response(request)
  File "/Users/dior/Documents/Channel_3rd_Backup_2021_0122/4_Work/Projects/Django-React-Full-Stack/TEST_TU/11_20_Test_Demo_Envi/lib/python3.6/site-packages/django/core/handlers/base.py", line 181, in _get_response
    response = wrapped_callback(request, *callback_args, **callback_kwargs)
  File "/Users/dior/Documents/Channel_3rd_Backup_2021_0122/4_Work/Projects/Django-React-Full-Stack/TEST_TU/11_20_Test_Demo_Envi/lib/python3.6/site-packages/django/views/decorators/csrf.py", line 54, in wrapped_view
    return view_func(*args, **kwargs)
  File "/Users/dior/Documents/Channel_3rd_Backup_2021_0122/4_Work/Projects/Django-React-Full-Stack/TEST_TU/11_20_Test_Demo_Envi/lib/python3.6/site-packages/django/views/generic/base.py", line 70, in view
    return self.dispatch(request, *args, **kwargs)
  File "/Users/dior/Documents/Channel_3rd_Backup_2021_0122/4_Work/Projects/Django-React-Full-Stack/TEST_TU/11_20_Test_Demo_Envi/lib/python3.6/site-packages/rest_framework/views.py", line 509, in dispatch
    response = self.handle_exception(exc)
  File "/Users/dior/Documents/Channel_3rd_Backup_2021_0122/4_Work/Projects/Django-React-Full-Stack/TEST_TU/11_20_Test_Demo_Envi/lib/python3.6/site-packages/rest_framework/views.py", line 469, in handle_exception
    self.raise_uncaught_exception(exc)
  File "/Users/dior/Documents/Channel_3rd_Backup_2021_0122/4_Work/Projects/Django-React-Full-Stack/TEST_TU/11_20_Test_Demo_Envi/lib/python3.6/site-packages/rest_framework/views.py", line 480, in raise_uncaught_exception
    raise exc
  File "/Users/dior/Documents/Channel_3rd_Backup_2021_0122/4_Work/Projects/Django-React-Full-Stack/TEST_TU/11_20_Test_Demo_Envi/lib/python3.6/site-packages/rest_framework/views.py", line 506, in dispatch
    response = handler(request, *args, **kwargs)
  File "/Users/dior/Documents/Channel_3rd_Backup_2021_0122/4_Work/Projects/Django-React-Full-Stack/TEST_TU/11_20_Test_Demo_Envi/lib/python3.6/site-packages/rest_framework/generics.py", line 230, in put
    return self.update(request, *args, **kwargs)
  File "/Users/dior/Documents/Channel_3rd_Backup_2021_0122/4_Work/Projects/Django-React-Full-Stack/TEST_TU/11_20_Test_Demo_Envi/lib/python3.6/site-packages/rest_framework/mixins.py", line 68, in update
    self.perform_update(serializer)
  File "/Users/dior/Documents/Channel_3rd_Backup_2021_0122/4_Work/Projects/Django-React-Full-Stack/TEST_TU/backend_Demo_Test/api/views.py", line 100, in perform_update
    memo_history = instance.memo_History or ''  # 防止 None 出现，默认空字符串
AttributeError: 'MemoRecord' object has no attribute 'memo_History'
"PUT /api/memo_records/update/2/ HTTP/1.1" 500 104079
Internal Server Error: /api/memo_records/update/3/
Traceback (most recent call last):
  File "/Users/dior/Documents/Channel_3rd_Backup_2021_0122/4_Work/Projects/Django-React-Full-Stack/TEST_TU/11_20_Test_Demo_Envi/lib/python3.6/site-packages/django/core/handlers/exception.py", line 47, in inner
    response = get_response(request)
  File "/Users/dior/Documents/Channel_3rd_Backup_2021_0122/4_Work/Projects/Django-React-Full-Stack/TEST_TU/11_20_Test_Demo_Envi/lib/python3.6/site-packages/django/core/handlers/base.py", line 181, in _get_response
    response = wrapped_callback(request, *callback_args, **callback_kwargs)
  File "/Users/dior/Documents/Channel_3rd_Backup_2021_0122/4_Work/Projects/Django-React-Full-Stack/TEST_TU/11_20_Test_Demo_Envi/lib/python3.6/site-packages/django/views/decorators/csrf.py", line 54, in wrapped_view
    return view_func(*args, **kwargs)
  File "/Users/dior/Documents/Channel_3rd_Backup_2021_0122/4_Work/Projects/Django-React-Full-Stack/TEST_TU/11_20_Test_Demo_Envi/lib/python3.6/site-packages/django/views/generic/base.py", line 70, in view
    return self.dispatch(request, *args, **kwargs)
  File "/Users/dior/Documents/Channel_3rd_Backup_2021_0122/4_Work/Projects/Django-React-Full-Stack/TEST_TU/11_20_Test_Demo_Envi/lib/python3.6/site-packages/rest_framework/views.py", line 509, in dispatch
    response = self.handle_exception(exc)
  File "/Users/dior/Documents/Channel_3rd_Backup_2021_0122/4_Work/Projects/Django-React-Full-Stack/TEST_TU/11_20_Test_Demo_Envi/lib/python3.6/site-packages/rest_framework/views.py", line 469, in handle_exception
    self.raise_uncaught_exception(exc)
  File "/Users/dior/Documents/Channel_3rd_Backup_2021_0122/4_Work/Projects/Django-React-Full-Stack/TEST_TU/11_20_Test_Demo_Envi/lib/python3.6/site-packages/rest_framework/views.py", line 480, in raise_uncaught_exception
    raise exc
  File "/Users/dior/Documents/Channel_3rd_Backup_2021_0122/4_Work/Projects/Django-React-Full-Stack/TEST_TU/11_20_Test_Demo_Envi/lib/python3.6/site-packages/rest_framework/views.py", line 506, in dispatch
    response = handler(request, *args, **kwargs)
  File "/Users/dior/Documents/Channel_3rd_Backup_2021_0122/4_Work/Projects/Django-React-Full-Stack/TEST_TU/11_20_Test_Demo_Envi/lib/python3.6/site-packages/rest_framework/generics.py", line 230, in put
    return self.update(request, *args, **kwargs)
  File "/Users/dior/Documents/Channel_3rd_Backup_2021_0122/4_Work/Projects/Django-React-Full-Stack/TEST_TU/11_20_Test_Demo_Envi/lib/python3.6/site-packages/rest_framework/mixins.py", line 68, in update
    self.perform_update(serializer)
  File "/Users/dior/Documents/Channel_3rd_Backup_2021_0122/4_Work/Projects/Django-React-Full-Stack/TEST_TU/backend_Demo_Test/api/views.py", line 100, in perform_update
    memo_history = instance.memo_history or ''  # 防止 None 出现，默认空字符串
AttributeError: 'MemoRecord' object has no attribute 'memo_history'
"PUT /api/memo_records/update/3/ HTTP/1.1" 500 104079
Internal Server Error: /api/memo_records/
Traceback (most recent call last):
  File "/Users/dior/Documents/Channel_3rd_Backup_2021_0122/4_Work/Projects/Django-React-Full-Stack/TEST_TU/11_20_Test_Demo_Envi/lib/python3.6/site-packages/django/core/handlers/exception.py", line 47, in inner
    response = get_response(request)
  File "/Users/dior/Documents/Channel_3rd_Backup_2021_0122/4_Work/Projects/Django-React-Full-Stack/TEST_TU/11_20_Test_Demo_Envi/lib/python3.6/site-packages/django/core/handlers/base.py", line 181, in _get_response
    response = wrapped_callback(request, *callback_args, **callback_kwargs)
  File "/Users/dior/Documents/Channel_3rd_Backup_2021_0122/4_Work/Projects/Django-React-Full-Stack/TEST_TU/11_20_Test_Demo_Envi/lib/python3.6/site-packages/django/views/decorators/csrf.py", line 54, in wrapped_view
    return view_func(*args, **kwargs)
  File "/Users/dior/Documents/Channel_3rd_Backup_2021_0122/4_Work/Projects/Django-React-Full-Stack/TEST_TU/11_20_Test_Demo_Envi/lib/python3.6/site-packages/django/views/generic/base.py", line 70, in view
    return self.dispatch(request, *args, **kwargs)
  File "/Users/dior/Documents/Channel_3rd_Backup_2021_0122/4_Work/Projects/Django-React-Full-Stack/TEST_TU/11_20_Test_Demo_Envi/lib/python3.6/site-packages/rest_framework/views.py", line 509, in dispatch
    response = self.handle_exception(exc)
  File "/Users/dior/Documents/Channel_3rd_Backup_2021_0122/4_Work/Projects/Django-React-Full-Stack/TEST_TU/11_20_Test_Demo_Envi/lib/python3.6/site-packages/rest_framework/views.py", line 469, in handle_exception
    self.raise_uncaught_exception(exc)
  File "/Users/dior/Documents/Channel_3rd_Backup_2021_0122/4_Work/Projects/Django-React-Full-Stack/TEST_TU/11_20_Test_Demo_Envi/lib/python3.6/site-packages/rest_framework/views.py", line 480, in raise_uncaught_exception
    raise exc
  File "/Users/dior/Documents/Channel_3rd_Backup_2021_0122/4_Work/Projects/Django-React-Full-Stack/TEST_TU/11_20_Test_Demo_Envi/lib/python3.6/site-packages/rest_framework/views.py", line 506, in dispatch
    response = handler(request, *args, **kwargs)
  File "/Users/dior/Documents/Channel_3rd_Backup_2021_0122/4_Work/Projects/Django-React-Full-Stack/TEST_TU/11_20_Test_Demo_Envi/lib/python3.6/site-packages/rest_framework/generics.py", line 243, in get
    return self.list(request, *args, **kwargs)
  File "/Users/dior/Documents/Channel_3rd_Backup_2021_0122/4_Work/Projects/Django-React-Full-Stack/TEST_TU/11_20_Test_Demo_Envi/lib/python3.6/site-packages/rest_framework/mixins.py", line 38, in list
    queryset = self.filter_queryset(self.get_queryset())
  File "/Users/dior/Documents/Channel_3rd_Backup_2021_0122/4_Work/Projects/Django-React-Full-Stack/TEST_TU/backend_Demo_Test/api/views.py", line 68, in get_queryset
    study_history_lines = study_history_content.splitlines()
AttributeError: 'StudyHistory' object has no attribute 'splitlines'
"GET /api/memo_records/ HTTP/1.1" 500 102832
Internal Server Error: /api/memo_records/
Traceback (most recent call last):
  File "/Users/dior/Documents/Channel_3rd_Backup_2021_0122/4_Work/Projects/Django-React-Full-Stack/TEST_TU/11_20_Test_Demo_Envi/lib/python3.6/site-packages/django/core/handlers/exception.py", line 47, in inner
    response = get_response(request)
  File "/Users/dior/Documents/Channel_3rd_Backup_2021_0122/4_Work/Projects/Django-React-Full-Stack/TEST_TU/11_20_Test_Demo_Envi/lib/python3.6/site-packages/django/core/handlers/base.py", line 181, in _get_response
    response = wrapped_callback(request, *callback_args, **callback_kwargs)
  File "/Users/dior/Documents/Channel_3rd_Backup_2021_0122/4_Work/Projects/Django-React-Full-Stack/TEST_TU/11_20_Test_Demo_Envi/lib/python3.6/site-packages/django/views/decorators/csrf.py", line 54, in wrapped_view
    return view_func(*args, **kwargs)
  File "/Users/dior/Documents/Channel_3rd_Backup_2021_0122/4_Work/Projects/Django-React-Full-Stack/TEST_TU/11_20_Test_Demo_Envi/lib/python3.6/site-packages/django/views/generic/base.py", line 70, in view
    return self.dispatch(request, *args, **kwargs)
  File "/Users/dior/Documents/Channel_3rd_Backup_2021_0122/4_Work/Projects/Django-React-Full-Stack/TEST_TU/11_20_Test_Demo_Envi/lib/python3.6/site-packages/rest_framework/views.py", line 509, in dispatch
    response = self.handle_exception(exc)
  File "/Users/dior/Documents/Channel_3rd_Backup_2021_0122/4_Work/Projects/Django-React-Full-Stack/TEST_TU/11_20_Test_Demo_Envi/lib/python3.6/site-packages/rest_framework/views.py", line 469, in handle_exception
    self.raise_uncaught_exception(exc)
  File "/Users/dior/Documents/Channel_3rd_Backup_2021_0122/4_Work/Projects/Django-React-Full-Stack/TEST_TU/11_20_Test_Demo_Envi/lib/python3.6/site-packages/rest_framework/views.py", line 480, in raise_uncaught_exception
    raise exc
  File "/Users/dior/Documents/Channel_3rd_Backup_2021_0122/4_Work/Projects/Django-React-Full-Stack/TEST_TU/11_20_Test_Demo_Envi/lib/python3.6/site-packages/rest_framework/views.py", line 506, in dispatch
    response = handler(request, *args, **kwargs)
  File "/Users/dior/Documents/Channel_3rd_Backup_2021_0122/4_Work/Projects/Django-React-Full-Stack/TEST_TU/11_20_Test_Demo_Envi/lib/python3.6/site-packages/rest_framework/generics.py", line 243, in get
    return self.list(request, *args, **kwargs)
  File "/Users/dior/Documents/Channel_3rd_Backup_2021_0122/4_Work/Projects/Django-React-Full-Stack/TEST_TU/11_20_Test_Demo_Envi/lib/python3.6/site-packages/rest_framework/mixins.py", line 38, in list
    queryset = self.filter_queryset(self.get_queryset())
  File "/Users/dior/Documents/Channel_3rd_Backup_2021_0122/4_Work/Projects/Django-React-Full-Stack/TEST_TU/backend_Demo_Test/api/views.py", line 68, in get_queryset
    study_history_lines = study_history_content.splitlines()
AttributeError: 'StudyHistory' object has no attribute 'splitlines'
"GET /api/memo_records/ HTTP/1.1" 500 102832
Internal Server Error: /api/memo_records/
Traceback (most recent call last):
  File "/Users/dior/Documents/Channel_3rd_Backup_2021_0122/4_Work/Projects/Django-React-Full-Stack/TEST_TU/11_20_Test_Demo_Envi/lib/python3.6/site-packages/django/core/handlers/exception.py", line 47, in inner
    response = get_response(request)
  File "/Users/dior/Documents/Channel_3rd_Backup_2021_0122/4_Work/Projects/Django-React-Full-Stack/TEST_TU/11_20_Test_Demo_Envi/lib/python3.6/site-packages/django/core/handlers/base.py", line 181, in _get_response
    response = wrapped_callback(request, *callback_args, **callback_kwargs)
  File "/Users/dior/Documents/Channel_3rd_Backup_2021_0122/4_Work/Projects/Django-React-Full-Stack/TEST_TU/11_20_Test_Demo_Envi/lib/python3.6/site-packages/django/views/decorators/csrf.py", line 54, in wrapped_view
    return view_func(*args, **kwargs)
  File "/Users/dior/Documents/Channel_3rd_Backup_2021_0122/4_Work/Projects/Django-React-Full-Stack/TEST_TU/11_20_Test_Demo_Envi/lib/python3.6/site-packages/django/views/generic/base.py", line 70, in view
    return self.dispatch(request, *args, **kwargs)
  File "/Users/dior/Documents/Channel_3rd_Backup_2021_0122/4_Work/Projects/Django-React-Full-Stack/TEST_TU/11_20_Test_Demo_Envi/lib/python3.6/site-packages/rest_framework/views.py", line 509, in dispatch
    response = self.handle_exception(exc)
  File "/Users/dior/Documents/Channel_3rd_Backup_2021_0122/4_Work/Projects/Django-React-Full-Stack/TEST_TU/11_20_Test_Demo_Envi/lib/python3.6/site-packages/rest_framework/views.py", line 469, in handle_exception
    self.raise_uncaught_exception(exc)
  File "/Users/dior/Documents/Channel_3rd_Backup_2021_0122/4_Work/Projects/Django-React-Full-Stack/TEST_TU/11_20_Test_Demo_Envi/lib/python3.6/site-packages/rest_framework/views.py", line 480, in raise_uncaught_exception
    raise exc
  File "/Users/dior/Documents/Channel_3rd_Backup_2021_0122/4_Work/Projects/Django-React-Full-Stack/TEST_TU/11_20_Test_Demo_Envi/lib/python3.6/site-packages/rest_framework/views.py", line 506, in dispatch
    response = handler(request, *args, **kwargs)
  File "/Users/dior/Documents/Channel_3rd_Backup_2021_0122/4_Work/Projects/Django-React-Full-Stack/TEST_TU/11_20_Test_Demo_Envi/lib/python3.6/site-packages/rest_framework/generics.py", line 243, in get
    return self.list(request, *args, **kwargs)
  File "/Users/dior/Documents/Channel_3rd_Backup_2021_0122/4_Work/Projects/Django-React-Full-Stack/TEST_TU/11_20_Test_Demo_Envi/lib/python3.6/site-packages/rest_framework/mixins.py", line 38, in list
    queryset = self.filter_queryset(self.get_queryset())
  File "/Users/dior/Documents/Channel_3rd_Backup_2021_0122/4_Work/Projects/Django-React-Full-Stack/TEST_TU/backend_Demo_Test/api/views.py", line 68, in get_queryset
    study_history_lines = study_history_content.splitlines()
AttributeError: 'StudyHistory' object has no attribute 'splitlines'
"GET /api/memo_records/ HTTP/1.1" 500 102859
Internal Server Error: /api/memo_records/
Traceback (most recent call last):
  File "/Users/dior/Documents/Channel_3rd_Backup_2021_0122/4_Work/Projects/Django-React-Full-Stack/TEST_TU/11_20_Test_Demo_Envi/lib/python3.6/site-packages/django/core/handlers/exception.py", line 47, in inner
    response = get_response(request)
  File "/Users/dior/Documents/Channel_3rd_Backup_2021_0122/4_Work/Projects/Django-React-Full-Stack/TEST_TU/11_20_Test_Demo_Envi/lib/python3.6/site-packages/django/core/handlers/base.py", line 181, in _get_response
    response = wrapped_callback(request, *callback_args, **callback_kwargs)
  File "/Users/dior/Documents/Channel_3rd_Backup_2021_0122/4_Work/Projects/Django-React-Full-Stack/TEST_TU/11_20_Test_Demo_Envi/lib/python3.6/site-packages/django/views/decorators/csrf.py", line 54, in wrapped_view
    return view_func(*args, **kwargs)
  File "/Users/dior/Documents/Channel_3rd_Backup_2021_0122/4_Work/Projects/Django-React-Full-Stack/TEST_TU/11_20_Test_Demo_Envi/lib/python3.6/site-packages/django/views/generic/base.py", line 70, in view
    return self.dispatch(request, *args, **kwargs)
  File "/Users/dior/Documents/Channel_3rd_Backup_2021_0122/4_Work/Projects/Django-React-Full-Stack/TEST_TU/11_20_Test_Demo_Envi/lib/python3.6/site-packages/rest_framework/views.py", line 509, in dispatch
    response = self.handle_exception(exc)
  File "/Users/dior/Documents/Channel_3rd_Backup_2021_0122/4_Work/Projects/Django-React-Full-Stack/TEST_TU/11_20_Test_Demo_Envi/lib/python3.6/site-packages/rest_framework/views.py", line 469, in handle_exception
    self.raise_uncaught_exception(exc)
  File "/Users/dior/Documents/Channel_3rd_Backup_2021_0122/4_Work/Projects/Django-React-Full-Stack/TEST_TU/11_20_Test_Demo_Envi/lib/python3.6/site-packages/rest_framework/views.py", line 480, in raise_uncaught_exception
    raise exc
  File "/Users/dior/Documents/Channel_3rd_Backup_2021_0122/4_Work/Projects/Django-React-Full-Stack/TEST_TU/11_20_Test_Demo_Envi/lib/python3.6/site-packages/rest_framework/views.py", line 506, in dispatch
    response = handler(request, *args, **kwargs)
  File "/Users/dior/Documents/Channel_3rd_Backup_2021_0122/4_Work/Projects/Django-React-Full-Stack/TEST_TU/11_20_Test_Demo_Envi/lib/python3.6/site-packages/rest_framework/generics.py", line 243, in get
    return self.list(request, *args, **kwargs)
  File "/Users/dior/Documents/Channel_3rd_Backup_2021_0122/4_Work/Projects/Django-React-Full-Stack/TEST_TU/11_20_Test_Demo_Envi/lib/python3.6/site-packages/rest_framework/mixins.py", line 38, in list
    queryset = self.filter_queryset(self.get_queryset())
  File "/Users/dior/Documents/Channel_3rd_Backup_2021_0122/4_Work/Projects/Django-React-Full-Stack/TEST_TU/backend_Demo_Test/api/views.py", line 68, in get_queryset
    study_history_lines = study_history_content.splitlines()
AttributeError: 'StudyHistory' object has no attribute 'splitlines'
"GET /api/memo_records/ HTTP/1.1" 500 102859
Internal Server Error: /api/memo_records/update/1/
Traceback (most recent call last):
  File "/Users/dior/Documents/Channel_3rd_Backup_2021_0122/4_Work/Projects/Django-React-Full-Stack/TEST_TU/11_20_Test_Demo_Envi/lib/python3.6/site-packages/django/core/handlers/exception.py", line 47, in inner
    response = get_response(request)
  File "/Users/dior/Documents/Channel_3rd_Backup_2021_0122/4_Work/Projects/Django-React-Full-Stack/TEST_TU/11_20_Test_Demo_Envi/lib/python3.6/site-packages/django/core/handlers/base.py", line 181, in _get_response
    response = wrapped_callback(request, *callback_args, **callback_kwargs)
  File "/Users/dior/Documents/Channel_3rd_Backup_2021_0122/4_Work/Projects/Django-React-Full-Stack/TEST_TU/11_20_Test_Demo_Envi/lib/python3.6/site-packages/django/views/decorators/csrf.py", line 54, in wrapped_view
    return view_func(*args, **kwargs)
  File "/Users/dior/Documents/Channel_3rd_Backup_2021_0122/4_Work/Projects/Django-React-Full-Stack/TEST_TU/11_20_Test_Demo_Envi/lib/python3.6/site-packages/django/views/generic/base.py", line 70, in view
    return self.dispatch(request, *args, **kwargs)
  File "/Users/dior/Documents/Channel_3rd_Backup_2021_0122/4_Work/Projects/Django-React-Full-Stack/TEST_TU/11_20_Test_Demo_Envi/lib/python3.6/site-packages/rest_framework/views.py", line 509, in dispatch
    response = self.handle_exception(exc)
  File "/Users/dior/Documents/Channel_3rd_Backup_2021_0122/4_Work/Projects/Django-React-Full-Stack/TEST_TU/11_20_Test_Demo_Envi/lib/python3.6/site-packages/rest_framework/views.py", line 469, in handle_exception
    self.raise_uncaught_exception(exc)
  File "/Users/dior/Documents/Channel_3rd_Backup_2021_0122/4_Work/Projects/Django-React-Full-Stack/TEST_TU/11_20_Test_Demo_Envi/lib/python3.6/site-packages/rest_framework/views.py", line 480, in raise_uncaught_exception
    raise exc
  File "/Users/dior/Documents/Channel_3rd_Backup_2021_0122/4_Work/Projects/Django-React-Full-Stack/TEST_TU/11_20_Test_Demo_Envi/lib/python3.6/site-packages/rest_framework/views.py", line 506, in dispatch
    response = handler(request, *args, **kwargs)
  File "/Users/dior/Documents/Channel_3rd_Backup_2021_0122/4_Work/Projects/Django-React-Full-Stack/TEST_TU/11_20_Test_Demo_Envi/lib/python3.6/site-packages/rest_framework/generics.py", line 230, in put
    return self.update(request, *args, **kwargs)
  File "/Users/dior/Documents/Channel_3rd_Backup_2021_0122/4_Work/Projects/Django-React-Full-Stack/TEST_TU/11_20_Test_Demo_Envi/lib/python3.6/site-packages/rest_framework/mixins.py", line 68, in update
    self.perform_update(serializer)
  File "/Users/dior/Documents/Channel_3rd_Backup_2021_0122/4_Work/Projects/Django-React-Full-Stack/TEST_TU/backend_Demo_Test/api/views.py", line 136, in perform_update
    serializer.save(study_history=updated_study_history, author=self.request.user)
  File "/Users/dior/Documents/Channel_3rd_Backup_2021_0122/4_Work/Projects/Django-React-Full-Stack/TEST_TU/11_20_Test_Demo_Envi/lib/python3.6/site-packages/rest_framework/serializers.py", line 203, in save
    self.instance = self.update(self.instance, validated_data)
  File "/Users/dior/Documents/Channel_3rd_Backup_2021_0122/4_Work/Projects/Django-React-Full-Stack/TEST_TU/11_20_Test_Demo_Envi/lib/python3.6/site-packages/rest_framework/serializers.py", line 1031, in update
    setattr(instance, attr, value)
  File "/Users/dior/Documents/Channel_3rd_Backup_2021_0122/4_Work/Projects/Django-React-Full-Stack/TEST_TU/11_20_Test_Demo_Envi/lib/python3.6/site-packages/django/db/models/fields/related_descriptors.py", line 220, in __set__
    self.field.remote_field.model._meta.object_name,
ValueError: Cannot assign "'StudyHistory object (2)\nReviewed on: 2024-12-05 15:12:16    |    Forget'": "MemoRecord.study_history" must be a "StudyHistory" instance.
"PUT /api/memo_records/update/1/ HTTP/1.1" 500 123456
